Workbook

Sheet log
A1: Date | B1: Site | C1: well.hieght | D1: top2WTE | E1: WT.distance.from.surface | F1: WTE | G1: Temp | H1: pH | I1: DO | J1: Sampled | L1: Notes
A2: 45569 | B2: 5GW1 | C2: 0.44 | E2: 0.065 | F2: ='well dims'!#REF!+E2 -> #REF! | H2: 6.6 | J2: Y | L2: Wtdepth measurements taken with extension on the well
A3: 45569 | B3: 5GW2 | C3: 0.415 | E3: 0.0575 | F3: ='well dims'!#REF!-E3 -> #REF! | H3: 5.97 | J3: Y | L3: Wtdepth measurements taken with extension on the well
A4: 45569 | B4: 5GW3 | C4: 0.755 | D4: 0.85 | E4: =C4-D4 -> -0.095 | H4: 5.82 | J4: Y | L4: Wtdepth measurements taken with extension on the well
A5: 45569 | B5: 5GW4 | C5: 0.75 | D5: 1.62 | E5: =C5-D5 -> -0.87 | H5: 5.19 | J5: Y | L5: Wtdepth measurements taken with extension on the well
A6: 45569 | B6: 5GW5 | C6: 0.09 | D6: 0.79 | E6: =C6-D6 -> -0.7 | F6: ='well dims'!#REF!+E6 -> #REF! | H6: 4.2 | J6: Y | L6: Wtdepth measurements taken with extension on the well
A7: 45569 | B7: 5GW6 | C7: 0.085 | D7: 1.23 | E7: =C7-D7 -> -1.145 | H7: 4.42 | J7: Y | L7: Wtdepth measurements taken with extension on the well
A8: 45569 | B8: 5GW7 | E8: 0.21 | H8: 6.12 | J8: Y | L8: Wtdepth measurements taken with extension on the well
A9: 45569 | B9: 6GW1 | C9: 0.16 | D9: 0.375 | E9: =C9-D9 -> -0.215 | H9: 3.94 | J9: N | L9: Pre Upland Installation
A10: 45569 | B10: 6GW2 | C10: 0.89 | E10: 0.03 | H10: 4.01 | J10: Y
A11: 45569 | B11: 6GW3 | C11: 0.04 | D11: 1.345 | E11: =C11-D11 -> -1.305 | F11: ='well dims'!#REF!+E11 -> #REF! | H11: 6.45 | J11: Y
A12: 45569 | B12: 6GW4 | C12: 0.25 | D12: 0.3 | E12: =C12-D12 -> -0.05 | H12: 4.29 | J12: Y
A13: 45569 | B13: 6GW5 | C13: 0.12 | D13: 1.4 | E13: =C13-D13 -> -1.28 | H13: 4.19 | J13: Y
A14: 45569 | B14: 9GW1 | C14: 0.26 | D14: 1.035 | E14: =C14-D14 -> -0.775 | F14: ='well dims'!#REF!+E14 -> #REF! | H14: 3.79 | J14: N
A15: 45569 | B15: 9GW2 | C15: 0 | D15: 1.17 | E15: =C15-D15 -> -1.17 | F15: ='well dims'!#REF!+E15 -> #REF! | H15: 3.93 | J15: N
A16: 45569 | B16: 9GW3 | C16: 0.74 | D16: 1.21 | E16: =C16-D16 -> -0.47 | F16: ='well dims'!#REF!+E16 -> #REF! | H16: 3.88 | J16: Y
A17: 45569 | B17: 9GW4 | C17: 0.33 | D17: 1.58 | E17: =C17-D17 -> -1.25 | F17: ='well dims'!#REF!+log!E17 -> #REF! | H17: 4.34 | J17: DID NOT PUMP
A18: 45687 | B18: 5GW1 | C18: 0.44 | D18: 0.415 | E18: =C18-D18 -> 0.025 | F18: ='well dims'!#REF!+E18 -> #REF! | G18: 13 | H18: 6.34 | J18: Y
A19: 45687 | B19: 5GW2 | C19: 0.415 | D19: 0.27 | E19: =D19-C19 -> -0.145 | F19: ='well dims'!#REF!-E19 -> #REF! | G19: 12.9 | H19: 6.17 | J19: Y
A20: 45687 | B20: 5GW3 | C20: 0.755 | E20: 0 | G20: 13.9 | H20: 5.85 | J20: Y | L20: at surface
A21: 45687 | B21: 5GW4 | C21: 0.24 | D21: 0.925 | E21: =C21-D21 -> -0.685 | G21: 15.7 | H21: 5.31 | J21: Y
A22: 45687 | B22: 5GW5 | C22: 0.09 | E22: 0.04 | F22: ='well dims'!#REF!+E22 -> #REF! | G22: 14.2 | H22: 4.47 | J22: Y
A23: 45687 | B23: 5GW6 | C23: 0.085 | D23: 0.545 | E23: =C23-D23 -> -0.46 | G23: 14.8 | H23: 4.27 | J23: Y
A24: 45687 | B24: 5GW7 | C24: 1.795 | E24: 0.41 | G24: 13.4 | H24: 5.76 | J24: Y
A25: 45687 | B25: 5GW8 | C25: 0.83 | E25: 0.04 | G25: 12.9 | H25: 5.65 | J25: Y
A26: 45687 | B26: 6GW1 | C26: 0.16 | D26: 0.45 | E26: =C26-D26 -> -0.29 | G26: 14.9 | H26: 4.37 | J26: Y
A27: 45687 | B27: 6GW2 | C27: 0.89 | E27: 0.035 | G27: 15 | H27: 4.27 | J27: Y
A28: 45687 | B28: 6GW3 | C28: 0.04 | D28: 1.36 | E28: =C28-D28 -> -1.32 | F28: ='well dims'!#REF!+E28 -> #REF! | G28: 17.1 | H28: 4.32 | J28: Y
A29: 45687 | B29: 6GW4 | C29: 0.25 | D29: 0.315 | E29: =C29-D29 -> -0.065 | G29: 15.3 | H29: 4.39 | J29: Y
A30: 45687 | B30: 6GW5 | C30: 0.12 | D30: 2.28 | E30: =C30-D30 -> -2.16 | G30: 18.4 | H30: 4.53 | J30: N
A31: 45687 | B31: 9GW1 | C31: 0.26 | D31: 0.545 | E31: =C31-D31 -> -0.285 | F31: ='well dims'!#REF!+E31 -> #REF! | G31: 13.2 | H31: 3.71 | J31: Y
A32: 45687 | B32: 9GW2 | C32: 0 | D32: 0.5 | E32: =C32-D32 -> -0.5 | F32: ='well dims'!#REF!+E32 -> #REF! | G32: 16 | H32: 3.9 | J32: Y
A33: 45687 | B33: 9GW3 | C33: 0.74 | D33: 1.275 | E33: =C33-D33 -> -0.535 | F33: ='well dims'!#REF!+E33 -> #REF! | G33: 16.1 | H33: 3.74 | J33: Y
A34: 45687 | B34: 9GW4 | C34: 0.33 | D34: 1.05 | E34: =C34-D34 -> -0.72 | F34: ='well dims'!#REF!+log!E34 -> #REF! | G34: 14.5 | H34: 4.06 | J34: Y
A35: 45687 | B35: 9GW5 | C35: 0.03 | D35: 0.81 | E35: =C35-D35 -> -0.78 | G35: 15.1 | H35: 4.39 | J35: Y
A36: 45728 | B36: 5GW1 | C36: 0.44 | D36: 0.455 | E36: =C36-D36 -> -0.015 | F36: ='well dims'!#REF!+E36 -> #REF! | G36: 16.3 | H36: 5.99 | J36: Y
A37: 45728 | B37: 5GW2 | C37: 0.415 | D37: 0.24 | E37: 0.145 | F37: ='well dims'!#REF!-E37 -> #REF! | G37: 16.2 | H37: 6.09 | J37: Y
A38: 45728 | B38: 5GW3 | C38: 0.755 | D38: 0.481 | E38: 0.282 | G38: 14.3 | H38: 5.93 | J38: Y
A39: 45728 | B39: 5GW4 | C39: 0.24 | D39: 0.759 | E39: =C39-D39 -> -0.519 | G39: 17.2 | H39: 5.02 | J39: Y
A40: 45728 | B40: 5GW5 | C40: 0.09 | E40: 0.281 | F40: ='well dims'!#REF!+E40 -> #REF! | G40: 15 | H40: 4.18 | J40: Y
...

Sheet well dims
A1: Site | B1: ID | C1: total.well.length | D1: well.height | E1: well.height.ext | F1: below.ground | G1: screen.extent | H1: distance.from.stream
A2: 5GW1 | B2: 5 | C2: 1.65 | D2: 0.44 | E2: ='well heightw extension '!C1/100 -> 1.215 | F2: =C2-D2 -> 1.21 | G2: 0.11 | H2: 4.2672
A3: 5GW2 | B3: 5 | C3: 1.01 | D3: 0.415 | E3: ='well heightw extension '!C2/100 -> 1.432 | F3: =C3-D3 -> 0.595 | G3: 0.11 | H3: 2.1336
A4: 5GW3 | B4: 5 | C4: 1.92 | D4: 0.755 | E4: =G4-D4 -> -0.955 | F4: =C4-D4 -> 1.165 | G4: -0.2 | H4: 1.2192
A5: 5GW4 | B5: 5 | C5: 1.57 | D5: 0.24 | E5: ='well heightw extension '!C4/100 -> 0.95 | F5: =C5-D5 -> 1.33 | G5: 0.11 | H5: 0.3048
A6: 5GW5 | B6: 5 | C6: 1.07 | D6: 0.09 | E6: ='well heightw extension '!C5/100 -> 0.8 | F6: =C6-D6 -> 0.98 | G6: 0 | H6: 4.8768
A7: 5GW6 | B7: 5 | C7: 1.34 | D7: 0.085 | E7: ='well heightw extension '!C6/100 -> 0.79 | F7: =C7-D7 -> 1.255 | G7: 0 | H7: 7.62
A8: 5GW8 | B8: 5 | C8: 2.61 | D8: 0.83 | F8: =C8-D8 -> 1.78 | G8: 0.2 | H8: 16.806672
A9: 6GW1 | B9: 6 | C9: 2.41 | D9: 0.16 | F9: =C9-D9 -> 2.25 | H9: 0.3048
A10: 6GW2 | B10: 6 | C10: 3.12 | D10: 0.89 | F10: =C10-D10 -> 2.23 | H10: 2.4384
A11: 6GW3 | B11: 6 | C11: 1.97 | D11: 0.04 | E11: ='well heightw extension '!C10/100 -> 0.87 | F11: =C11-D11 -> 1.93 | G11: 0 | H11: 7.9248
A12: 6GW4 | B12: 6 | C12: 3.04 | D12: 0.25 | F12: =C12-D12 -> 2.79 | G12: 0.2 | H12: 1.524
A13: 6GW5 | B13: 6 | C13: 4.425 | D13: 0.12 | E13: ='well heightw extension '!C12/100 -> 1.11 | F13: =C13-D13 -> 4.305 | G13: -0.85 | H13: 7.62
A14: 9GW1 | B14: 9 | C14: 1.13 | D14: 0.26 | E14: ='well heightw extension '!C13/100 -> 0.9 | F14: =C14-D14 -> 0.87 | G14: 0.12 | H14: 0.3048
A15: 9GW2 | B15: 9 | C15: 1.77 | D15: 0 | E15: ='well heightw extension '!C14/100 -> 0.74 | F15: =C15-D15 -> 1.77 | G15: 0 | H15: 1.524
A16: 9GW3 | B16: 9 | C16: 1.08 | D16: 0 | E16: ='well heightw extension '!C15/100 -> 0.74 | F16: =C16-D16 -> 1.08 | G16: 0 | H16: 4.2672
A17: 9GW4 | B17: 9 | C17: 1.58 | D17: 0.33 | E17: ='well heightw extension '!C16/100 -> 1.1 | F17: =C17-D17 -> 1.25 | G17: 0.15 | H17: 0.3
A18: 9GW5 | B18: 9 | C18: 1.9 | D18: 0.03 | E18: ='well heightw extension '!C17/100 -> 0.725 | F18: =C18-D18 -> 1.87 | G18: 0 | H18: 20

Sheet screen extent
A1: Site | B1: extent (datum=ground)
A2: 5GW1 | B2: 0.11
A3: 5GW2 | B3: 0.11
A4: 5GW3 | B4: -0.2
A5: 5GW4 | B5: 0.11
A6: 5GW5 | B6: 0
A7: 5GW6 | B7: 0
A8: 5GW8 | B8: 0.2
A9: 6GW1
A10: 6GW2
A11: 6GW3 | B11: 0
A12: 6GW4 | B12: 0.2
A13: 6GW5 | B13: -0.85
A14: 9GW1 | B14: 0.12
A15: 9GW2 | B15: 0
A16: 9GW3 | B16: 0
A17: 9GW4 | B17: 0.15
A18: 9GW5 | B18: 0

Sheet elevation
A1: Site | B1: surface.elevation | C1: stream.bed.elevation
A2: 5GW1 | B2: 32.99 | C2: 28.436 | D2: =B2-C2 -> 4.554
A3: 5GW2 | B3: 32.519 | C3: 28.436 | D3: =B3-C3 -> 4.083
A4: 5GW3 | B4: 35.409 | C4: 28.436 | D4: =B4-C4 -> 6.973
A5: 5GW4 | B5: 33.191 | C5: 28.436 | D5: =B5-C5 -> 4.755
A6: 5GW5 | B6: 32.14 | C6: 28.436 | D6: =B6-C6 -> 3.704
A7: 5GW6 | B7: 32.064 | C7: 28.436 | D7: =B7-C7 -> 3.628
A8: 5GW8 | B8: 33.777 | C8: 28.436 | D8: =B8-C8 -> 5.341
A9: 6GW1 | B9: 44.038 | C9: 41.503 | D9: =B9-C9 -> 2.535
A10: 6GW2 | B10: 52.57 | C10: 41.503 | D10: =B10-C10 -> 11.067
A11: 6GW3 | B11: 42.025 | C11: 41.503 | D11: =B11-C11 -> 0.522
A12: 6GW4 | B12: 41.163 | C12: 41.503 | D12: =B12-C12 -> -0.34
A13: 6GW5 | B13: 38.178 | C13: 41.503 | D13: =B13-C13 -> -3.325
... A18: 9GW5 | B18: 40.115 | C18: 38.848 | D18: =B18-C18 -> 1.267

Sheet total well length 
A1: 45442 | B1: 5GW1 | C1: 1.06 | E1: 45463 | F1: 5GW1 | G1: 1.06 | I1: 45484 | J1: 5GW1 | M1: 1.06 | O1: 5GW1 | P1: 45940 | Q1: 1.65
A2: 45442 | B2: 5GW2 | C2: 1.01 | E2: 45463 | F2: 5GW2 | G2: 1.01 | I2: 45484 | J2: 5GW2 | M2: 1.01 | O2: 5GW2 | P2: 45940 | Q2: 1.01
A3: 45442 | B3: 5GW3 | C3: 1.04 | E3: 45463 | F3: 5GW3 | G3: 1.92 | I3: 45484 | J3: 5GW3 | O3: 5GW3 | P3: 45940 | Q3: 1.92
A4: 45442 | B4: 5GW4 | C4: 1.57 | E4: 45463 | F4: 5GW4 | G4: 1.56 | I4: 45484 | J4: 5GW4 | K4: 1.57 | M4: 1.57 | O4: 5GW4 | P4: 45940 | Q4: 1.58
A5: 45442 | B5: 5GW5 | C5: 1.09 | E5: 45463 | F5: 5GW5 | G5: 1.31 | I5: 45484 | J5: 5GW5 | O5: 5GW5 | P5: 45940 | Q5: 1.05
A6: 45442 | B6: 5GW6 | C6: 1.34 | E6: 45463 | F6: 5GW6 | G6: 1.34 | I6: 45484 | J6: 5GW6 | K6: 1.34 | M6: 1.34 | O6: 5GW6 | P6: 45940 | Q6: 1.34
A7: 45442 | B7: 5GW7 | E7: 45463 | F7: 5GW7 | G7: 3.26 | I7: 45484 | J7: 5GW7 | O7: 5GW8 | P7: 45940 | Q7: 2.61
A8: 45442 | B8: 6GW1 | C8: 1.12 | E8: 45463 | F8: 6GW1 | G8: 2.41 | I8: 45484 | J8: 6GW1 | K8: 0.424 | O8: 6GW1 | P8: 45940 | Q8: 2.41
A9: 45442 | B9: 6GW2 | C9: 0.75 | E9: 45463 | F9: 6GW2 | G9: 3.1 | I9: 45484 | J9: 6GW2 | K9: 3.12 | M9: 3.12 | O9: 6GW2 | P9: 45940 | Q9: 3.12
A10: 45442 | B10: 6GW3 | C10: 1.96 | E10: 45463 | F10: 6GW3 | G10: 2.74 | I10: 45484 | J10: 6GW3 | K10: 2.17 | O10: 6GW3 | P10: 45940 | Q10: 1.97
A11: 45442 | B11: 6GW4 | C11: 0.72 | E11: 45463 | F11: 6GW4 | G11: 2.09 | I11: 45484 | J11: 6GW4 | K11: 3.6 | O11: 6GW4 | P11: 45940 | Q11: 3.04
A12: 45442 | B12: 6GW5 | C12: 2.56 | E12: 45463 | F12: 6GW5 | G12: 4.25 | I12: 45484 | J12: 6GW5 | K12: 4.425 | M12: 4.425 | O12: 6GW5 | P12: 45940 | Q12: 3.31
A13: 45442 | B13: 9GW1 | C13: 1.13 | E13: 45463 | F13: 9GW1 | G13: 1.71 | I13: 45484 | J13: 9GW1 | K13: 1.13 | M13: 1.13 | O13: 9GW1 | P13: 45940 | Q13: 1.14
A14: 45442 | B14: 9GW2 | C14: 1.27 | E14: 45463 | F14: 9GW2 | G14: 2.48 | I14: 45484 | J14: 9GW2 | K14: 2.25 | O14: 9GW2 | P14: 45940 | Q14: 1.77
A15: 45442 | B15: 9GW3 | C15: 0.97 | E15: 45463 | F15: 9GW3 | G15: 2.18 | I15: 45484 | J15: 9GW3 | K15: 2.465 | O15: 9GW3 | P15: 45940 | Q15: 1.08
A16: 45442 | B16: 9GW4 | C16: 1.59 | E16: 45463 | F16: 9GW4 | G16: 2.35 | I16: 45484 | J16: 9GW4 | K16: 1.56 | M16: =AVERAGE(C16,K16) -> 1.575 | O16: 9GW4 | P16: 45940 | Q16: 1.58
O17: 9GW5 | P17: 45940 | Q17: 1.9

Sheet well heightw extension 
A1: 45940 | B1: 5GW1 | C1: 121.5
A2: 45940 | B2: 5GW2 | C2: 143.2
A3: 45940 | B3: 5GW3
A4: 45940 | B4: 5GW4 | C4: 95
A5: 45940 | B5: 5GW5 | C5: 80
A6: 45940 | B6: 5GW6 | C6: 79
A7: 45940 | B7: 5GW8
A8: 45940 | B8: 6GW1
A9: 45940 | B9: 6GW2
A10: 45940 | B10: 6GW3 | C10: 87
A11: 45940 | B11: 6GW4
A12: 45940 | B12: 6GW5 | C12: 111
A13: 45940 | B13: 9GW1 | C13: 90
A14: 45940 | B14: 9GW2 | C14: 74
A15: 45940 | B15: 9GW3 | C15: 74
A16: 45940 | B16: 9GW4 | C16: 110
A17: 45940 | B17: 9GW5 | C17: 72.5

Sheet well height_raw
A1: 45635 | B1: 5GW1 | C1: 0.44 | E1: 45667 | F1: 5GW1 | G1: 0.44 | I1: 45502 | J1: 5GW1 | M1: 45764 | N1: 5GW1 | O1: 1.2 | Q1: 45940 | R1: 5GW1 | S1: 43.7 | T1: =S1/100 -> 0.437 | V1: 0.44
A2: 45635 | B2: 5GW2 | C2: 0.39 | E2: 45667 | F2: 5GW2 | G2: 0.39 | I2: 45502 | J2: 5GW2 | K2: 0.42 | M2: 45764 | N2: 5GW2 | O2: 0.41 | Q2: 45940 | R2: 5GW2 | S2: 41.5 | T2: =S2/100 -> 0.415 | V2: 0.415
A3: 45635 | B3: 5GW3 | C3: 0.6 | E3: 45667 | F3: 5GW3 | G3: 0.75 | I3: 45502 | J3: 5GW3 | K3: 0.755 | M3: 45764 | N3: 5GW3 | O3: 0.735 | Q3: 45940 | R3: 5GW3 | S3: 79 | T3: =S3/100 -> 0.79 | V3: 0.755
A4: 45635 | B4: 5GW4 | C4: 0.24 | E4: 45667 | F4: 5GW4 | G4: 0.21 | I4: 45502 | J4: 5GW4 | K4: 0.239 | M4: 45764 | N4: 5GW4 | O4: 0.22 | Q4: 45940 | R4: 5GW4 | S4: 26 | T4: =S4/100 -> 0.26 | V4: 0.24
A5: 45635 | B5: 5GW5 | C5: 0.11 | E5: 45667 | F5: 5GW5 | G5: 0.09 | I5: 45502 | J5: 5GW5 | K5: 0.75 | M5: 45764 | N5: 5GW5 | O5: 0.09 | Q5: 45940 | R5: 5GW5 | S5: 10 | T5: =S5/100 -> 0.1 | V5: 0.09
A6: 45635 | B6: 5GW6 | C6: 0.74 | E6: 45667 | F6: 5GW6 | G6: 0.04 | I6: 45502 | J6: 5GW6 | K6: 0.07 | M6: 45764 | N6: 5GW6 | O6: 0.065 | Q6: 45940 | R6: 5GW6 | S6: 8.5 | T6: =S6/100 -> 0.085 | V6: 0.085
A7: 45635 | B7: 5GW7 | C7: 1.73 | E7: 45667 | F7: 5GW7 | M7: 45764 | N7: 5GW7 | Q7: 45940 | R7: 5GW7 | T7: =S7/100 -> 0
A8: 45635 | B8: 5GW8 | C8: 0.81 | E8: 45667 | F8: 5GW8 | G8: 0.83 | M8: 45764 | N8: 5GW8 | O8: 0.82 | Q8: 45940 | R8: 5GW8 | S8: 102 | T8: =S8/100 -> 1.02 | V8: 0.83
A9: 45635 | B9: 6GW1 | C9: 0.15 | E9: 45667 | F9: 6GW1 | G9: 0.14 | I9: 45502 | J9: 6GW1 | K9: 0.078 | M9: 45764 | N9: 6GW1 | O9: 0.16 | Q9: 45940 | R9: 6GW1 | S9: 17.5 | T9: =S9/100 -> 0.175 | V9: 0.16
A10: 45635 | B10: 6GW2 | C10: 0.8 | E10: 45667 | F10: 6GW2 | G10: 0.79 | I10: 45502 | J10: 6GW2 | K10: 0.84 | M10: 45764 | N10: 6GW2 | O10: 0.76 | Q10: 45940 | R10: 6GW2 | S10: 89 | T10: =S10/100 -> 0.89 | V10: 0.89
A11: 45635 | B11: 6GW3 | C11: 0.02 | E11: 45667 | F11: 6GW3 | G11: 0.02 | I11: 45502 | J11: 6GW3 | K11: 0 | M11: 45764 | N11: 6GW3 | O11: 0.04 | Q11: 45940 | R11: 6GW3 | S11: 7 | T11: =S11/100 -> 0.07 | V11: 0.04
A12: 45635 | B12: 6GW4 | C12: 0.2 | E12: 45667 | F12: 6GW4 | G12: 0.2 | I12: 45502 | J12: 6GW4 | K12: 0.81 | M12: 45764 | N12: 6GW4 | O12: 0.195 | Q12: 45940 | R12: 6GW4 | S12: 21 | T12: =S12/100 -> 0.21 | V12: 0.25
A13: 45635 | B13: 6GW5 | C13: 1 | E13: 45667 | F13: 6GW5 | I13: 45502 | J13: 6GW5 | K13: 1 | M13: 45764 | N13: 6GW5 | O13: 0.08 | Q13: 45940 | R13: 6GW5 | S13: 12 | T13: =S13/100 -> 0.12 | V13: 0.12
A14: 45635 | B14: 9GW1 | C14: 0.23 | E14: 45667 | F14: 9GW1 | G14: 0.27 | I14: 45502 | J14: 9GW1 | K14: 0.245 | M14: 45764 | N14: 9GW1 | O14: 0.215 | Q14: 45940 | R14: 9GW1 | S14: 26 | T14: =S14/100 -> 0.26 | V14: 0.26
A15: 45635 | B15: 9GW2 | C15: 0 | E15: 45667 | F15: 9GW2 | G15: 0 | I15: 45502 | J15: 9GW2 | K15: 0 | M15: 45764 | N15: 9GW2 | O15: 0 | Q15: 45940 | R15: 9GW2 | S15: 0 | T15: =S15/100 -> 0 | V15: 0
A16: 45635 | B16: 9GW3 | C16: 0.68 | E16: 45667 | F16: 9GW3 | G16: 0 | I16: 45502 | J16: 9GW3 | K16: 0 | M16: 45764 | N16: 9GW3 | O16: 0 | Q16: 45940 | R16: 9GW3 | S16: 0 | T16: =S16/100 -> 0 | V16: 0
A17: 45635 | B17: 9GW4 | C17: 0.3 | E17: 45667 | F17: 9GW4 | G17: 0.31 | I17: 45502 | J17: 9GW4 | K17: 0.345 | M17: 45764 | N17: 9GW4 | O17: 0.335 | Q17: 45940 | R17: 9GW4 | S17: 33 | T17: =S17/100 -> 0.33 | V17: 0.33
A18: 45635 | B18: 9GW5 | C18: 0.69 | E18: 45667 | F18: 9GW5 | G18: 0.03 | M18: 45764 | N18: 9GW5 | O18: 0.03 | Q18: 45940 | R18: 9GW5 | S18: 3 | T18: =S18/100 -> 0.03 | V18: 0.03

Sheet scope elevations
A1: Site | B1: ID | C1: scope.height.ft | D1: elevation.ft | E1: notes | F1: scope.surface.elevation
A2: 5GW1 | B2: 5 | C2: 5.4 | D2: 4.34 | F2: =$D$9-D2 -> 1.84
A3: 5GW2 | B3: 5 | C3: 5.4 | D3: 5.24 | F3: =$D$9-D3 -> 0.94
A4: 5GW3 | B4: 5 | C4: 5.4 | D4: 5.8 | F4: =$D$9-D4 -> 0.38
A5: 5GW4 | B5: 5 | C5: 5.4 | D5: 4.09 | F5: =$D$9-D5 -> 2.09
A6: 5GW5 | B6: 5 | C6: 5.4 | D6: 6.04 | F6: =$D$9-D6 -> 0.14
A7: 5GW6 | B7: 5 | C7: 5.4 | D7: 3.71 | F7: =$D$9-D7 -> 2.47
A8: 5GW8 | B8: 5 | C8: 5.4 | D8: 3.41 | E8: 2ft from well | F8: =$D$9-D8 -> 2.77
A9: 5GW0 | B9: 5 | C9: 5.4 | D9: 6.18 | F9: =$D$9-D9 -> 0
A10: 6GW1 | B10: 6 | C10: 4.96 | D10: 4.22 | F10: =$D$15-D10 -> 1.96
A11: 6GW2 | B11: 6 | C11: 4.96 | D11: 4.98 | F11: =$D$15-D11 -> 1.2
A12: 6GW3 | B12: 6 | C12: 4.96 | D12: 2.69 | F12: =$D$15-D12 -> 3.49
A13: 6GW4 | B13: 6 | C13: 4.96 | D13: 3.09 | F13: =$D$15-D13 -> 3.09
A14: 6GW5 | B14: 6 | C14: 4.96 | D14: 1.9 | F14: =$D$15-D14 -> 4.28
A15: 6GW0 | B15: 6 | C15: 4.96 | D15: 6.18 | F15: =$D$15-D15 -> 0
A16: 9GW1 | B16: 9 | D16: =AVERAGE(6.7,6.74) -> 6.72 | F16: =$D$20-D16 -> 1.44
A17: 9GW2 | B17: 9 | D17: =AVERAGE(5.93,5.94) -> 5.935 | F17: =$D$20-D17 -> 2.225
A18: 9GW3 | B18: 9 | D18: =AVERAGE(6.15,6.1) -> 6.125 | F18: =$D$20-D18 -> 2.035
A19: 9GW4 | B19: 9 | D19: =AVERAGE(5.74,5.65) -> 5.695 | F19: =$D$20-D19 -> 2.465
A20: 9GW0 | B20: 9 | D20: =7.66+0.5 -> 8.16 | F20: =$D$20-D20 -> 0
A21: 9GW5 | B21: 9 | D21: =AVERAGE(5.74,5.66) -> 5.7 | F21: =$D$20-D21 -> 2.46

Sheet scope elevations 04172026
A1: Stream | B1: GW | C1: elevation.ft | D1: scope.surface.elevation | E1: Stream_2 | F1: GW_2 | G1: Scope_2
A2: 5 | B2: 4 | C2: 4.14 | D2: =$C$3-C2 -> 4.26 | E2: 5 | F2: 1 | G2: 3.94 | H2: =G2-$G$4 -> 0.7
A3: 5 | B3: 0 | C3: 8.4 | D3: =$C$3-C3 -> 0 | E3: 5 | F3: 2 | G3: 4.34 | H3: =G3-$G$4 -> 1.1
A4: 5 | B4: 5 | C4: 6.58 | D4: =$C$3-C4 -> 1.82 | E4: 5 | F4: 3 | G4: 3.24 | H4: =G4-$G$4 -> 0
A5: 5 | B5: 6 | C5: 4.08 | D5: =$C$3-C5 -> 4.32 | E5: 5 | F5: 0 | G5: 7.58
A6: 5 | B6: 8 | C6: 1.72 | D6: =$C$3-C6 -> 6.68
A7: 5 | B7: 3 | C7: 4.4 | D7: =$C$3-C7 -> 4
A8: 5 | B8: 2 | C8: =C7+H3 -> 5.5 | D8: =$C$3-C8 -> 2.9
A9: 5 | B9: 1 | C9: =C7+H2 -> 5.1 | D9: =$C$3-C9 -> 3.3
